<?xml version="1.0"?>
<robot name="wheel_robot" xmlns:xacro="http://ros.org/wiki/xacro">
  <!-- MODELS -->
  <xacro:include filename="$(find joy_ps3_gazebo)/meshes/sensor/hokuyo.urdf.xacro"/>
  <xacro:include filename="$(find joy_ps3_gazebo)/meshes/camera/camera.urdf.xacro"/>
  <xacro:include filename="$(find joy_ps3_gazebo)/meshes/imu.urdf.xacro"/>
  <material name="blue">
    <color rgba="0 0 0.8 1"/>
  </material>
  <material name="black">
    <color rgba="0 0 0 1"/>
  </material>
  <material name="white">
    <color rgba="1 1 1 1"/>
  </material>
  <xacro:property name="bodylen" value="0.1" />  
  <xacro:macro name="default_inertial" params="mass">
    <inertial>
      <mass value="${mass}" />
      <inertia ixx="1.0" ixy="0.0" ixz="0.0" iyy="1.0" iyz="0.0" izz="1.0" />
    </inertial>
  </xacro:macro>

  <xacro:macro name="wheel_macro" params="parent prefix xyz">
    <joint name="${prefix}_joint" type="continuous">
      <origin xyz="${xyz}" rpy="${radians(-90)} 0 0"/>
      <parent link="${parent}"/>
      <child  link="${prefix}_link"/>
      <axis xyz="0 0 1" />
    </joint>
    <transmission name="${prefix}_trans" type="SimpleTransmission">
      <type>transmission_interface/SimpleTransmission</type>
      <actuator name="${prefix}_motor">
        <mechanicalReduction>1</mechanicalReduction>
      </actuator>
      <joint name="${prefix}_joint">
        <hardwareInterface>hardware_interface/VelocityJointInterface</hardwareInterface>
      </joint>
    </transmission>
    <link name="${prefix}_link">
      <inertial>
        <origin xyz="0 0 0" rpy="0 0 0"/>
        <mass value="0.1"/>
        <inertia ixx="0.0001" ixy="0.0" ixz="0.0" iyy="0.0001" iyz="0.0" izz="0.0001"/>
      </inertial>
      <visual>
        <geometry>
          <cylinder radius="0.05" length="0.02" />
        </geometry>
        <material name="blue"/>
      </visual>
      <collision>
        <geometry>
          <cylinder radius="0.05" length="0.02" />
        </geometry>
      </collision>
    </link>
    <gazebo reference="${prefix}_link">
      <material>Gazebo/Blue</material>
      <mu1 value="2.5" />
      <mu2 value="2.5" />
      <kp value="50000" />
      <kd value="10" />
    </gazebo>
  </xacro:macro> 

  <link name="base_link"/>

  <joint name="body_joint" type="fixed">
    <parent link="base_link"/>
    <child  link="body_link"/>
    <origin xyz="-0.07 0 0.07" rpy="0 0 0"/>
  </joint>
  <link name="body_link">
    <inertial>
      <origin xyz="0 0 0" rpy="0 0 0"/>
      <mass value="1.0"/>
      <inertia ixx="0.001" ixy="0.0" ixz="0.0" iyy="0.001" iyz="0.0" izz="0.001"/>
    </inertial>
    <visual>
      <origin xyz="0 0 0" rpy="0 0 0" />
      <geometry>
        <box size="0.24 0.18 0.06" />
      </geometry>
      <material name="black"/>
    </visual>
    <collision>
      <origin xyz="0 0 0" rpy="0 0 0" />
      <geometry>
        <box size="0.24 0.178 0.06" />
      </geometry>
    </collision>
  </link>
  <gazebo reference="body_link">
	  <material>Gazebo/Black</material>
  </gazebo>

  <xacro:wheel_macro prefix="left_wheel"  parent="base_link" xyz="0 0.1 0.05"/>
  <xacro:wheel_macro prefix="right_wheel" parent="base_link" xyz="0 -0.1 0.05"/>

  <joint name="ball_joint" type="fixed">
    <parent link="base_link"/>
    <child  link="ball_link"/>
    <origin xyz="-0.14 0 0.04" rpy="0 0 0"/>
  </joint>
  <link name="ball_link">
    <visual>
      <origin xyz="0 0 0" rpy="0 0 0" />
      <geometry>
        <sphere radius="0.04" />
      </geometry>
      <material name="black"/>
    </visual>
    <collision>
      <origin xyz="0 0 0" rpy="0 0 0" />
      <geometry>
        <sphere radius="0.04" />
      </geometry>
      <material name="black"/>
    </collision>
  </link>
  <gazebo reference="ball_link">
    <material>Gazebo/Black</material>
    <mu1 value="0.5" />
    <mu2 value="0.5" />
  </gazebo>

  <!-- Laser link and plugin -->
  <xacro:hokuyo_laser xyz="0 0 ${0.04 + 0.02}" 
	  rpy="0 0 0"
	  parent="body_link" length="0.04" radius="0.045">
  </xacro:hokuyo_laser>
   
  <!--Imu link and plugin-->
  <xacro:imu_sensor xyz="-0.1 0 ${0.04 + 0.01}" 
	  rpy="0 0 0"
          parent="body_link">
  </xacro:imu_sensor>

  <!--Camera link and plugin-->
  <xacro:camera_sensor xyz="0 0 ${0.04 + 0.02 + 0.04}" 
	  rpy="0 0 0"
          parent="body_link">
  </xacro:camera_sensor>

  <!-- plugin to connect with gazebo  -->
  <gazebo>
    <plugin name="gazebo_ros_control" filename="libgazebo_ros_control.so">
      <robotNamespace>/wheel_robot</robotNamespace>
      <robotSimType>gazebo_ros_control/DefaultRobotHWSim</robotSimType>
      <legacyModeNS>true</legacyModeNS>
    </plugin>
  </gazebo>
  
  <!-- gazebo plugin for Wheel Odometry such as nav_msgs, tf -->
  <gazebo>
    <plugin name="ground_truth" filename="libgazebo_ros_p3d.so">
      <frameName>world</frameName>
      <bodyName>base_link</bodyName>
      <topicName>/tracker</topicName>
      <updateRate>10.0</updateRate>
    </plugin>
  </gazebo>
</robot>
